Workbook

Sheet 양식
A2: 구분
B3: 네이처 (경주) | C3: 네이처 (천북) | D3: 아세아테크 돔 | E3: 그린밸리 (이앤컴퍼니) 돔 | G3: 충주그린 (에코비트 그린.충주) 돔 | H3: 포항그린 (그린바이로) | I3: 하동군 생폐처리장 (단가 협의중) | J3: KD환경. 경주 | K3: 리뉴랜드 신경주 돔 | L3: 에코랜드 (제넨바이오) | M3: 예비3 | N3: 예비4 | O3: 예비5 | P3: 침출수 반입량 | Q3: 침출수 반입 비율 (%) | R3: 군위군청 25.2.26~ (최초반입) | S3: 월성 원자력 | T3: 한울 원자력 | U3: 고리 원자력 | V3: 새울 원자력 | W3: 에코프로 머티리얼즈 | X3: 엠엔비 그린어스 | Y3: 영풍석포 25.02.26 일시물량 | Z3: 무안환경 비전 | AA3: 에코프로 예비3 | AB3: 에코프로 예비4 | AC3: 에코프로 예비5 | AD3: SK스페셜티 | AE3: 비정기 기타일반계 | AF3: 기타일반계 합계 | AG3: 성진영농 | AH3: 천보 | AI3: 예비1 | AJ3: 예비2 | AK3: 그 외 일반계 | AL3: 일반계 합계 | AM3: 예비1 | AN3: 예비2 | AO3: 산계 | AP3: 알칼리계 | AQ3: 예비1 | AR3: 예비2 | AS3: 예비3 | AT3: 포스코 퓨처엠 양극재 | AV3: 반입량 (9,000) | AW3: 처리량 (10,640)
A4: 수치 | B4: TOC 2,406 | C4: TOC 2,484 | D4: TOC 3,378 | E4: TOC 895 | G4: TOC 1,002 | H4: TOC 1,053 | J4: TOC 2,618 | K4: TOC 214 | L4: TOC 2,728 | R4: TOC 19 | T4: TOC 5.8 | V4: TOC 34 | W4: TN 1.2 | X4: TN 1.0 | Y4: TN 0.5 | Z4: 7.22재개 | AF4: 화학처리 제외 | AG4: TN 9 | AH4: TN 27 | AT4: 107TK
A5: 1 | P5: =SUM(B5:O5) -> 0 | Q5: =P5/AV5 -> #DIV/0! | AF5: =SUM(R5:AE5) -> 0 | AL5: =AG5+AK5+AH5 -> 0 | AV5: =P5+AF5+AL5+AM5+AP5+AO5+AT5 -> 0
A6: 2 | P6: =SUM(B6:O6) -> 0 | Q6: =P6/AV6 -> #DIV/0! | AF6: =SUM(R6:AE6) -> 0 | AL6: =AG6+AK6+AH6 -> 0 | AV6: =P6+AF6+AL6+AM6+AP6+AO6+AT6 -> 0
A7: 3 | P7: =SUM(B7:O7) -> 0 | Q7: =P7/AV7 -> #DIV/0! | AF7: =SUM(R7:AE7) -> 0 | AL7: =AG7+AK7+AH7 -> 0 | AV7: =P7+AF7+AL7+AM7+AP7+AO7+AT7 -> 0
A8: 4 | P8: =SUM(B8:O8) -> 0 | Q8: =P8/AV8 -> #DIV/0! | AF8: =SUM(R8:AE8) -> 0 | AL8: =AG8+AK8+AH8 -> 0 | AV8: =P8+AF8+AL8+AM8+AP8+AO8+AT8 -> 0
A9: 5 | P9: =SUM(B9:O9) -> 0 | Q9: =P9/AV9 -> #DIV/0! | AF9: =SUM(R9:AE9) -> 0 | AL9: =AG9+AK9+AH9 -> 0 | AV9: =P9+AF9+AL9+AM9+AP9+AO9+AT9 -> 0
A10: 6 | P10: =SUM(B10:O10) -> 0 | Q10: =P10/AV10 -> #DIV/0! | AF10: =SUM(R10:AE10) -> 0 | AL10: =AG10+AK10+AH10 -> 0 | AV10: =P10+AF10+AL10+AM10+AP10+AO10+AT10 -> 0
A11: 7 | P11: =SUM(B11:O11) -> 0 | Q11: =P11/AV11 -> #DIV/0! | AF11: =SUM(R11:AE11) -> 0 | AL11: =AG11+AK11+AH11 -> 0 | AV11: =P11+AF11+AL11+AM11+AP11+AO11+AT11 -> 0
A12: 8 | P12: =SUM(B12:O12) -> 0 | Q12: =P12/AV12 -> #DIV/0! | AF12: =SUM(R12:AE12) -> 0 | AL12: =AG12+AK12+AH12 -> 0 | AV12: =P12+AF12+AL12+AM12+AP12+AO12+AT12 -> 0
A13: 9 | P13: =SUM(B13:O13) -> 0 | Q13: =P13/AV13 -> #DIV/0! | AF13: =SUM(R13:AE13) -> 0 | AL13: =AG13+AK13+AH13 -> 0 | AV13: =P13+AF13+AL13+AM13+AP13+AO13+AT13 -> 0
A14: 10 | P14: =SUM(B14:O14) -> 0 | Q14: =P14/AV14 -> #DIV/0! | AF14: =SUM(R14:AE14) -> 0 | AL14: =AG14+AK14+AH14 -> 0 | AV14: =P14+AF14+AL14+AM14+AP14+AO14+AT14 -> 0
A15: 11 | P15: =SUM(B15:O15) -> 0 | Q15: =P15/AV15 -> #DIV/0! | AF15: =SUM(R15:AE15) -> 0 | AL15: =AG15+AK15+AH15 -> 0 | AV15: =P15+AF15+AL15+AM15+AP15+AO15+AT15 -> 0
A16: 12 | P16: =SUM(B16:O16) -> 0 | Q16: =P16/AV16 -> #DIV/0! | AF16: =SUM(R16:AE16) -> 0 | AL16: =AG16+AK16+AH16 -> 0 | AV16: =P16+AF16+AL16+AM16+AP16+AO16+AT16 -> 0
... A33: 29 | P33: =SUM(B33:O33) -> 0 | Q33: =P33/AV33 -> #DIV/0! | AF33: =SUM(R33:AE33) -> 0 | AL33: =AG33+AK33+AH33 -> 0 | AV33: =P33+AF33+AL33+AM33+AP33+AO33+AT33 -> 0
A34: 30 | P34: =SUM(B34:O34) -> 0 | Q34: =P34/AV34 -> #DIV/0! | AF34: =SUM(R34:AE34) -> 0 | AL34: =AG34+AK34+AH34 -> 0 | AV34: =P34+AF34+AL34+AM34+AP34+AO34+AT34 -> 0 | AX34: `
A35: 31 | P35: =SUM(B35:O35) -> 0 | Q35: =P35/AV35 -> #DIV/0! | AF35: =SUM(R35:AE35) -> 0 | AL35: =AG35+AK35+AH35 -> 0 | AV35: =P35+AF35+AL35+AM35+AP35+AO35+AT35 -> 0
A36: 월계 | B36: =SUM(B5:B35) -> 0 | C36: =SUM(C5:C35) -> 0 | D36: =SUM(D5:D35) -> 0 | E36: =SUM(E5:E35) -> 0 | F36: =SUM(F5:F35) -> 0 | G36: =SUM(G5:G35) -> 0 | H36: =SUM(H5:H35) -> 0 | I36: =SUM(I5:I35) -> 0 | ... O36: =SUM(O5:O35) -> 0 | P36: =SUM(B36:O36) -> 0 | Q36: =AVERAGE(Q5:Q35) -> #DIV/0! | R36: =SUM(R5:R35) -> 0 | S36: =SUM(S5:S35) -> 0 | T36: =SUM(T5:T35) -> 0 | U36: =SUM(U5:U35) -> 0 | V36: =SUM(V5:V35) -> 0 | W36: =SUM(W5:W35) -> 0 | X36: =SUM(X5:X35) -> 0 | Y36: =SUM(Y5:Y35) -> 0 | ... AE36: =SUM(AE5:AE35) -> 0 | AF36: =SUM(R36:AE36) -> 0 | AG36: =SUM(AG5:AG35) -> 0 | AH36: =SUM(AH5:AH35) -> 0 | AI36: =SUM(AI5:AI35) -> 0 | AJ36: =SUM(AJ5:AJ35) -> 0 | AK36: =SUM(AK5:AK35) -> 0 | AL36: =AG36+AK36+AH36 -> 0 | AM36: =SUM(AM5:AM35) -> 0 | AO36: =SUM(AO5:AO35) -> 0 | AP36: =SUM(AP5:AP35) -> 0 | AQ36: =SUM(AQ5:AQ35) -> 0 | AR36: =SUM(AR5:AR35) -> 0 | AS36: =SUM(AS5:AS35) -> 0 | AT36: =SUM(AT5:AT35) -> 0 | AV36: =SUM(AV5:AV35) -> 0 | AW36: =SUM(AW5:AW35) -> 0
A37: 전월 | M37: 0 | N37: 0 | O37: 0 | R37: 0 | S37: 0 | T37: 0 | U37: 0 | V37: 0 | W37: 0 | AM37: 0 | AU37: 달성률 | AV37: =AV36/'2026년 폐수반입현황'!AY5 -> #DIV/0! | AW37: =AW36/'2026년 폐수반입현황'!AV5 -> #DIV/0!
A38: 전월대비 | B38: =B36-B37 -> 0 | C38: =C36-C37 -> 0 | D38: =D36-D37 -> 0 | E38: =E36-E37 -> 0 | F38: =F36-F37 -> 0 | G38: =G36-G37 -> 0 | H38: =H36-H37 -> 0 | I38: =I36-I37 -> 0 | ... AK38: =AK36-AK37 -> 0 | AL38: =AG38+AK38+AT38 -> 0 | AM38: =AM36-AM37 -> 0 | AO38: 64.69 | AP38: =AP36-AP37 -> 0 | AQ38: =AQ36-AQ37 -> 0 | AR38: =AR36-AR37 -> 0 | AS38: =AS36-AS37 -> 0 | AT38: =AT36-AT37 -> 0
A39: 년 누계 | M39: 0 | N39: 0 | O39: 0 | AM39: 0
A40: 고농도 침출수 비율 | B40: =B36/P36 -> #DIV/0! | C40: =C36/P36 -> #DIV/0! | D40: =D36/P36 -> #DIV/0! | E40: =E36/P36 -> #DIV/0! | F40: =F36/T36 -> #DIV/0! | G40: =G36/P36 -> #DIV/0! | H40: =H36/P36 -> #DIV/0! | I40: =I36/W36 -> #DIV/0! | J40: =J36/P36 -> #DIV/0! | K40: =K36/P36 -> #DIV/0! | L40: =L36/P36 -> #DIV/0! | P40: =B40+C40+D40+E40+G40+J40+K40+H40+L40 -> #DIV/0! | AY40: 기타일반계 원가절감 데이터
B41: =B40+C40 -> #DIV/0! | D41: =D40+E40+G40+J40+L40+H40 -> #DIV/0! | P41: =B41+C41+D41+E41+G41+J41+K41 -> #DIV/0! | AY41: 월간 | BA41: 기타일반계 | BB41: 포스코양극재
AY42: 반입량 | BA42: =AF36 -> 0 | BB42: =AT36 -> 0
AY43: 약품비 합계 | BA43: 2479 | BB43: 2479
AY44: 탈수처리비용 | BA44: 540 | BB44: 540
AY45: 절감비용 | BA45: =(BA43+BA44)*BA42 -> 0 | BB45: =(BB43+BB44)*BB42 -> 0
AY46: 총 반입량 | BA46: =BA42+BB42+BC42 -> 0
AY47: 총 절감비용 | BA47: =BA46*BA48 -> 0
AY48: 톤당 절감비용 | BA48: 3019
AY49: 절감 약품 종류 : NaOH, H2SO4, Fe2(SO4)3, Cation ★전처리약품
AY52: 1월 | AZ52: 목표 처리량 : 10,640 | BB52: 목표 반입량 : 9,000
AY53: 날짜 | AZ53: 처리량 | BA53: 달성률 | BB53: 반입량 | BC53: 달성률
AY54: 29 | AZ54: =AW36 -> 0 | BA54: =AW37 -> #DIV/0! | BB54: =AV36 -> 0 | BC54: =AV37 -> #DIV/0!

Sheet 1월
A1: 2026년 1월 폐수수탁 일일 반입 및 실적 현황
A2: 구분
B3: 네이처 (경주) | C3: 네이처 (천북) | D3: 아세아테크 돔 | E3: 그린밸리 (이앤컴퍼니) 돔 | G3: 충주그린 (에코비트 그린.충주) 돔 | H3: 포항그린 (그린바이로) | I3: 하동군 생폐처리장 (단가 협의중) | J3: KD환경. 경주 | K3: 리뉴랜드 신경주 돔 | L3: 에코랜드 (제넨바이오) | M3: 예비3 | N3: 예비4 | O3: 예비5 | P3: 침출수 반입량 | Q3: 침출수 반입 비율 (%) | R3: 군위군청 25.2.26~ (최초반입) | S3: 월성 원자력 | T3: 한울 원자력 | U3: 고리 원자력 | V3: 새울 원자력 | W3: 에코프로 머티리얼즈 | X3: 엠엔비 그린어스 | Y3: 영풍석포 25.02.26 일시물량 | Z3: 무안환경 비전 | AA3: 에코프로 예비3 | AB3: 에코프로 예비4 | AC3: 에코프로 예비5 | AD3: SK스페셜티 | AE3: 비정기 기타일반계 | AF3: 기타일반계 합계 | AG3: 성진영농 | AH3: 천보 | AI3: 예비1 | AJ3: 예비2 | AK3: 그 외 일반계 | AL3: 일반계 합계 | AM3: 예비1 | AN3: 예비2 | AO3: 산계 | AP3: 알칼리계 | AQ3: 예비1 | AR3: 예비2 | AS3: 예비3 | AT3: 포스코 퓨처엠 양극재 | AV3: 반입량 (9,000) | AW3: 처리량 (10,640)
A4: 수치 | B4: TOC 2,406 | C4: TOC 2,484 | D4: TOC 3,378 | E4: TOC 895 | G4: TOC 1,002 | H4: TOC 1,053 | J4: TOC 2,618 | K4: TOC 214 | L4: TOC 2,728 | R4: TOC 19 | T4: TOC 5.8 | V4: TOC 34 | W4: TN 1.2 | X4: TN 1.0 | Y4: TN 0.5 | Z4: 7.22재개 | AF4: 화학처리 제외 | AG4: TN 9 | AH4: TN 27 | AT4: 107TK
A5: 1 | P5: =SUM(B5:O5) -> 0 | Q5: =P5/AV5 -> #DIV/0! | AF5: =SUM(R5:AE5) -> 0 | AL5: =AG5+AK5+AH5 -> 0 | AV5: =P5+AF5+AL5+AM5+AP5+AO5+AT5 -> 0
A6: 2 | P6: =SUM(B6:O6) -> 0 | Q6: =P6/AV6 -> #DIV/0! | AF6: =SUM(R6:AE6) -> 0 | AL6: =AG6+AK6+AH6 -> 0 | AV6: =P6+AF6+AL6+AM6+AP6+AO6+AT6 -> 0
A7: 3 | P7: =SUM(B7:O7) -> 0 | Q7: =P7/AV7 -> #DIV/0! | AF7: =SUM(R7:AE7) -> 0 | AL7: =AG7+AK7+AH7 -> 0 | AV7: =P7+AF7+AL7+AM7+AP7+AO7+AT7 -> 0
A8: 4 | P8: =SUM(B8:O8) -> 0 | Q8: =P8/AV8 -> #DIV/0! | AF8: =SUM(R8:AE8) -> 0 | AL8: =AG8+AK8+AH8 -> 0 | AV8: =P8+AF8+AL8+AM8+AP8+AO8+AT8 -> 0
A9: 5 | P9: =SUM(B9:O9) -> 0 | Q9: =P9/AV9 -> #DIV/0! | AF9: =SUM(R9:AE9) -> 0 | AL9: =AG9+AK9+AH9 -> 0 | AV9: =P9+AF9+AL9+AM9+AP9+AO9+AT9 -> 0
A10: 6 | P10: =SUM(B10:O10) -> 0 | Q10: =P10/AV10 -> #DIV/0! | AF10: =SUM(R10:AE10) -> 0 | AL10: =AG10+AK10+AH10 -> 0 | AV10: =P10+AF10+AL10+AM10+AP10+AO10+AT10 -> 0
A11: 7 | P11: =SUM(B11:O11) -> 0 | Q11: =P11/AV11 -> #DIV/0! | AF11: =SUM(R11:AE11) -> 0 | AL11: =AG11+AK11+AH11 -> 0 | AV11: =P11+AF11+AL11+AM11+AP11+AO11+AT11 -> 0
A12: 8 | P12: =SUM(B12:O12) -> 0 | Q12: =P12/AV12 -> #DIV/0! | AF12: =SUM(R12:AE12) -> 0 | AL12: =AG12+AK12+AH12 -> 0 | AV12: =P12+AF12+AL12+AM12+AP12+AO12+AT12 -> 0
A13: 9 | P13: =SUM(B13:O13) -> 0 | Q13: =P13/AV13 -> #DIV/0! | AF13: =SUM(R13:AE13) -> 0 | AL13: =AG13+AK13+AH13 -> 0 | AV13: =P13+AF13+AL13+AM13+AP13+AO13+AT13 -> 0
A14: 10 | P14: =SUM(B14:O14) -> 0 | Q14: =P14/AV14 -> #DIV/0! | AF14: =SUM(R14:AE14) -> 0 | AL14: =AG14+AK14+AH14 -> 0 | AV14: =P14+AF14+AL14+AM14+AP14+AO14+AT14 -> 0
A15: 11 | P15: =SUM(B15:O15) -> 0 | Q15: =P15/AV15 -> #DIV/0! | AF15: =SUM(R15:AE15) -> 0 | AL15: =AG15+AK15+AH15 -> 0 | AV15: =P15+AF15+AL15+AM15+AP15+AO15+AT15 -> 0
A16: 12 | P16: =SUM(B16:O16) -> 0 | Q16: =P16/AV16 -> #DIV/0! | AF16: =SUM(R16:AE16) -> 0 | AL16: =AG16+AK16+AH16 -> 0 | AV16: =P16+AF16+AL16+AM16+AP16+AO16+AT16 -> 0
... A24: 20 | P24: =SUM(B24:O24) -> 0 | Q24: =P24/AV24 -> #DIV/0! | AF24: =SUM(R24:AE24) -> 0 | AL24: =AG24+AK24+AH24 -> 0 | AV24: =P24+AF24+AL24+AM24+AP24+AO24+AT24 -> 0
A25: 21 | G25: 2 | P25: =SUM(B25:O25) -> 2 | Q25: =P25/AV25 -> 1 | AF25: =SUM(R25:AE25) -> 0 | AL25: =AG25+AK25+AH25 -> 0 | AV25: =P25+AF25+AL25+AM25+AP25+AO25+AT25 -> 2
A26: 22 | P26: =SUM(B26:O26) -> 0 | Q26: =P26/AV26 -> #DIV/0! | AF26: =SUM(R26:AE26) -> 0 | AL26: =AG26+AK26+AH26 -> 0 | AV26: =P26+AF26+AL26+AM26+AP26+AO26+AT26 -> 0
A27: 23 | H27: 2 | P27: =SUM(B27:O27) -> 2 | Q27: =P27/AV27 -> 1 | AF27: =SUM(R27:AE27) -> 0 | AL27: =AG27+AK27+AH27 -> 0 | AV27: =P27+AF27+AL27+AM27+AP27+AO27+AT27 -> 2
A28: 24 | P28: =SUM(B28:O28) -> 0 | Q28: =P28/AV28 -> #DIV/0! | AF28: =SUM(R28:AE28) -> 0 | AL28: =AG28+AK28+AH28 -> 0 | AV28: =P28+AF28+AL28+AM28+AP28+AO28+AT28 -> 0
A29: 25 | H29: 2 | P29: =SUM(B29:O29) -> 2 | Q29: =P29/AV29 -> 1 | AF29: =SUM(R29:AE29) -> 0 | AL29: =AG29+AK29+AH29 -> 0 | AV29: =P29+AF29+AL29+AM29+AP29+AO29+AT29 -> 2
A30: 26 | L30: 2 | P30: =SUM(B30:O30) -> 2 | Q30: =P30/AV30 -> 1 | AF30: =SUM(R30:AE30) -> 0 | AL30: =AG30+AK30+AH30 -> 0 | AV30: =P30+AF30+AL30+AM30+AP30+AO30+AT30 -> 2
A31: 27 | P31: =SUM(B31:O31) -> 0 | Q31: =P31/AV31 -> #DIV/0! | AF31: =SUM(R31:AE31) -> 0 | AL31: =AG31+AK31+AH31 -> 0 | AV31: =P31+AF31+AL31+AM31+AP31+AO31+AT31 -> 0
A32: 28 | P32: =SUM(B32:O32) -> 0 | Q32: =P32/AV32 -> #DIV/0! | AF32: =SUM(R32:AE32) -> 0 | AL32: =AG32+AK32+AH32 -> 0 | AV32: =P32+AF32+AL32+AM32+AP32+AO32+AT32 -> 0
A33: 29 | P33: =SUM(B33:O33) -> 0 | Q33: =P33/AV33 -> #DIV/0! | AF33: =SUM(R33:AE33) -> 0 | AL33: =AG33+AK33+AH33 -> 0 | AV33: =P33+AF33+AL33+AM33+AP33+AO33+AT33 -> 0
A34: 30 | P34: =SUM(B34:O34) -> 0 | Q34: =P34/AV34 -> #DIV/0! | AF34: =SUM(R34:AE34) -> 0 | AL34: =AG34+AK34+AH34 -> 0 | AV34: =P34+AF34+AL34+AM34+AP34+AO34+AT34 -> 0 | AX34: `
A35: 31 | P35: =SUM(B35:O35) -> 0 | Q35: =P35/AV35 -> #DIV/0! | AF35: =SUM(R35:AE35) -> 0 | AL35: =AG35+AK35+AH35 -> 0 | AV35: =P35+AF35+AL35+AM35+AP35+AO35+AT35 -> 0
A36: 월계 | B36: =SUM(B5:B35) -> 0 | C36: =SUM(C5:C35) -> 0 | D36: =SUM(D5:D35) -> 0 | E36: =SUM(E5:E35) -> 0 | F36: =SUM(F5:F35) -> 0 | G36: =SUM(G5:G35) -> 2 | H36: =SUM(H5:H35) -> 4 | I36: =SUM(I5:I35) -> 0 | ... O36: =SUM(O5:O35) -> 0 | P36: =SUM(B36:O36) -> 8 | Q36: =AVERAGE(Q5:Q35) -> #DIV/0! | R36: =SUM(R5:R35) -> 0 | S36: =SUM(S5:S35) -> 0 | T36: =SUM(T5:T35) -> 0 | U36: =SUM(U5:U35) -> 0 | V36: =SUM(V5:V35) -> 0 | W36: =SUM(W5:W35) -> 0 | X36: =SUM(X5:X35) -> 0 | Y36: =SUM(Y5:Y35) -> 0 | ... AE36: =SUM(AE5:AE35) -> 0 | AF36: =SUM(R36:AE36) -> 0 | AG36: =SUM(AG5:AG35) -> 0 | AH36: =SUM(AH5:AH35) -> 0 | AI36: =SUM(AI5:AI35) -> 0 | AJ36: =SUM(AJ5:AJ35) -> 0 | AK36: =SUM(AK5:AK35) -> 0 | AL36: =AG36+AK36+AH36 -> 0 | AM36: =SUM(AM5:AM35) -> 0 | AO36: =SUM(AO5:AO35) -> 0 | AP36: =SUM(AP5:AP35) -> 0 | AQ36: =SUM(AQ5:AQ35) -> 0 | AR36: =SUM(AR5:AR35) -> 0 | AS36: =SUM(AS5:AS35) -> 0 | AT36: =SUM(AT5:AT35) -> 0 | AV36: =SUM(AV5:AV35) -> 8 | AW36: =SUM(AW5:AW35) -> 0
A37: 전월 | M37: 0 | N37: 0 | O37: 0 | R37: 0 | S37: 0 | T37: 0 | U37: 0 | V37: 0 | W37: 0 | AM37: 0 | AU37: 달성률 | AV37: =AV36/'2026년 폐수반입현황'!AY5 -> #DIV/0! | AW37: =AW36/'2026년 폐수반입현황'!AV5 -> #DIV/0!
A38: 전월대비 | B38: =B36-B37 -> 0 | C38: =C36-C37 -> 0 | D38: =D36-D37 -> 0 | E38: =E36-E37 -> 0 | F38: =F36-F37 -> 0 | G38: =G36-G37 -> 2 | H38: =H36-H37 -> 4 | I38: =I36-I37 -> 0 | ... AK38: =AK36-AK37 -> 0 | AL38: =AG38+AK38+AT38 -> 0 | AM38: =AM36-AM37 -> 0 | AO38: 64.69 | AP38: =AP36-AP37 -> 0 | AQ38: =AQ36-AQ37 -> 0 | AR38: =AR36-AR37 -> 0 | AS38: =AS36-AS37 -> 0 | AT38: =AT36-AT37 -> 0
A39: 년 누계 | M39: 0 | N39: 0 | O39: 0 | AM39: 0
A40: 고농도 침출수 비율 | B40: =B36/P36 -> 0 | C40: =C36/P36 -> 0 | D40: =D36/P36 -> 0 | E40: =E36/P36 -> 0 | F40: =F36/T36 -> #DIV/0! | G40: =G36/P36 -> 0.25 | H40: =H36/P36 -> 0.5 | I40: =I36/W36 -> #DIV/0! | J40: =J36/P36 -> 0 | K40: =K36/P36 -> 0 | L40: =L36/P36 -> 0.25 | P40: =B40+C40+D40+E40+G40+J40+K40+H40+L40 -> 1 | AY40: 기타일반계 원가절감 데이터
B41: =B40+C40 -> 0 | D41: =D40+E40+G40+J40+L40+H40 -> 1 | P41: =B41+C41+D41+E41+G41+J41+K41 -> 1 | AY41: 월간 | BA41: 기타일반계 | BB41: 포스코양극재
AY42: 반입량 | BA42: =AF36 -> 0 | BB42: =AT36 -> 0
AY43: 약품비 합계 | BA43: 2479 | BB43: 2479
AY44: 탈수처리비용 | BA44: 540 | BB44: 540
AY45: 절감비용 | BA45: =(BA43+BA44)*BA42 -> 0 | BB45: =(BB43+BB44)*BB42 -> 0
AY46: 총 반입량 | BA46: =BA42+BB42+BC42 -> 0
AY47: 총 절감비용 | BA47: =BA46*BA48 -> 0
...

Sheet 2월
A1: 2026년 2월 폐수수탁 일일 반입 및 실적 현황
A2: 구분
B3: 네이처 (경주) | C3: 네이처 (천북) | D3: 아세아테크 돔 | E3: 그린밸리 (이앤컴퍼니) 돔 | G3: 충주그린 (에코비트 그린.충주) 돔 | H3: 포항그린 (그린바이로) | I3: 하동군 생폐처리장 (단가 협의중) | J3: KD환경. 경주 | K3: 리뉴랜드 신경주 돔 | L3: 에코랜드 (제넨바이오) | M3: 예비3 | N3: 예비4 | O3: 예비5 | P3: 침출수 반입량 | Q3: 침출수 반입 비율 (%) | R3: 군위군청 25.2.26~ (최초반입) | S3: 월성 원자력 | T3: 한울 원자력 | U3: 고리 원자력 | V3: 새울 원자력 | W3: 에코프로 머티리얼즈 | X3: 엠엔비 그린어스 | Y3: 영풍석포 25.02.26 일시물량 | Z3: 무안환경 비전 | AA3: 에코프로 예비3 | AB3: 에코프로 예비4 | AC3: 에코프로 예비5 | AD3: SK스페셜티 | AE3: 비정기 기타일반계 | AF3: 기타일반계 합계 | AG3: 성진영농 | AH3: 천보 | AI3: 예비1 | AJ3: 예비2 | AK3: 그 외 일반계 | AL3: 일반계 합계 | AM3: 예비1 | AN3: 예비2 | AO3: 산계 | AP3: 알칼리계 | AQ3: 예비1 | AR3: 예비2 | AS3: 예비3 | AT3: 포스코 퓨처엠 양극재 | AV3: 반입량 (9,000) | AW3: 처리량 (10,640)
A4: 수치 | B4: TOC 2,406 | C4: TOC 2,484 | D4: TOC 3,378 | E4: TOC 895 | G4: TOC 1,002 | H4: TOC 1,053 | J4: TOC 2,618 | K4: TOC 214 | L4: TOC 2,728 | R4: TOC 19 | T4: TOC 5.8 | V4: TOC 34 | W4: TN 1.2 | X4: TN 1.0 | Y4: TN 0.5 | Z4: 7.22재개 | AF4: 화학처리 제외 | AG4: TN 9 | AH4: TN 27 | AT4: 107TK
A5: 1 | P5: =SUM(B5:O5) -> 0 | Q5: =P5/AV5 -> #DIV/0! | AF5: =SUM(R5:AE5) -> 0 | AL5: =AG5+AK5+AH5 -> 0 | AV5: =P5+AF5+AL5+AM5+AP5+AO5+AT5 -> 0
A6: 2 | P6: =SUM(B6:O6) -> 0 | Q6: =P6/AV6 -> #DIV/0! | AF6: =SUM(R6:AE6) -> 0 | AL6: =AG6+AK6+AH6 -> 0 | AV6: =P6+AF6+AL6+AM6+AP6+AO6+AT6 -> 0
A7: 3 | P7: =SUM(B7:O7) -> 0 | Q7: =P7/AV7 -> #DIV/0! | AF7: =SUM(R7:AE7) -> 0 | AL7: =AG7+AK7+AH7 -> 0 | AV7: =P7+AF7+AL7+AM7+AP7+AO7+AT7 -> 0
A8: 4 | P8: =SUM(B8:O8) -> 0 | Q8: =P8/AV8 -> #DIV/0! | AF8: =SUM(R8:AE8) -> 0 | AL8: =AG8+AK8+AH8 -> 0 | AV8: =P8+AF8+AL8+AM8+AP8+AO8+AT8 -> 0
A9: 5 | P9: =SUM(B9:O9) -> 0 | Q9: =P9/AV9 -> #DIV/0! | AF9: =SUM(R9:AE9) -> 0 | AL9: =AG9+AK9+AH9 -> 0 | AV9: =P9+AF9+AL9+AM9+AP9+AO9+AT9 -> 0
A10: 6 | P10: =SUM(B10:O10) -> 0 | Q10: =P10/AV10 -> #DIV/0! | AF10: =SUM(R10:AE10) -> 0 | AL10: =AG10+AK10+AH10 -> 0 | AV10: =P10+AF10+AL10+AM10+AP10+AO10+AT10 -> 0
A11: 7 | P11: =SUM(B11:O11) -> 0 | Q11: =P11/AV11 -> #DIV/0! | AF11: =SUM(R11:AE11) -> 0 | AL11: =AG11+AK11+AH11 -> 0 | AV11: =P11+AF11+AL11+AM11+AP11+AO11+AT11 -> 0
A12: 8 | P12: =SUM(B12:O12) -> 0 | Q12: =P12/AV12 -> #DIV/0! | AF12: =SUM(R12:AE12) -> 0 | AL12: =AG12+AK12+AH12 -> 0 | AV12: =P12+AF12+AL12+AM12+AP12+AO12+AT12 -> 0
A13: 9 | P13: =SUM(B13:O13) -> 0 | Q13: =P13/AV13 -> #DIV/0! | AF13: =SUM(R13:AE13) -> 0 | AL13: =AG13+AK13+AH13 -> 0 | AV13: =P13+AF13+AL13+AM13+AP13+AO13+AT13 -> 0
A14: 10 | P14: =SUM(B14:O14) -> 0 | Q14: =P14/AV14 -> #DIV/0! | AF14: =SUM(R14:AE14) -> 0 | AL14: =AG14+AK14+AH14 -> 0 | AV14: =P14+AF14+AL14+AM14+AP14+AO14+AT14 -> 0
A15: 11 | P15: =SUM(B15:O15) -> 0 | Q15: =P15/AV15 -> #DIV/0! | AF15: =SUM(R15:AE15) -> 0 | AL15: =AG15+AK15+AH15 -> 0 | AV15: =P15+AF15+AL15+AM15+AP15+AO15+AT15 -> 0
A16: 12 | P16: =SUM(B16:O16) -> 0 | Q16: =P16/AV16 -> #DIV/0! | AF16: =SUM(R16:AE16) -> 0 | AL16: =AG16+AK16+AH16 -> 0 | AV16: =P16+AF16+AL16+AM16+AP16+AO16+AT16 -> 0
... A32: 28 | P32: =SUM(B32:O32) -> 0 | Q32: =P32/AV32 -> #DIV/0! | AF32: =SUM(R32:AE32) -> 0 | AL32: =AG32+AK32+AH32 -> 0 | AV32: =P32+AF32+AL32+AM32+AP32+AO32+AT32 -> 0
P33: =SUM(B33:O33) -> 0 | Q33: =P33/AV33 -> #DIV/0! | AF33: =SUM(R33:AE33) -> 0 | AL33: =AG33+AK33+AH33 -> 0 | AV33: =P33+AF33+AL33+AM33+AP33+AO33+AT33 -> 0
P34: =SUM(B34:O34) -> 0 | Q34: =P34/AV34 -> #DIV/0! | AF34: =SUM(R34:AE34) -> 0 | AL34: =AG34+AK34+AH34 -> 0 | AV34: =P34+AF34+AL34+AM34+AP34+AO34+AT34 -> 0 | AX34: `
P35: =SUM(B35:O35) -> 0 | Q35: =P35/AV35 -> #DIV/0! | AF35: =SUM(R35:AE35) -> 0 | AL35: =AG35+AK35+AH35 -> 0 | AV35: =P35+AF35+AL35+AM35+AP35+AO35+AT35 -> 0
A36: 월계 | B36: =SUM(B5:B35) -> 0 | C36: =SUM(C5:C35) -> 0 | D36: =SUM(D5:D35) -> 0 | E36: =SUM(E5:E35) -> 0 | F36: =SUM(F5:F35) -> 0 | G36: =SUM(G5:G35) -> 0 | H36: =SUM(H5:H35) -> 0 | I36: =SUM(I5:I35) -> 0 | ... O36: =SUM(O5:O35) -> 0 | P36: =SUM(B36:O36) -> 0 | Q36: =AVERAGE(Q5:Q35) -> #DIV/0! | R36: =SUM(R5:R35) -> 0 | S36: =SUM(S5:S35) -> 0 | T36: =SUM(T5:T35) -> 0 | U36: =SUM(U5:U35) -> 0 | V36: =SUM(V5:V35) -> 0 | W36: =SUM(W5:W35) -> 0 | X36: =SUM(X5:X35) -> 0 | Y36: =SUM(Y5:Y35) -> 0 | ... AE36: =SUM(AE5:AE35) -> 0 | AF36: =SUM(R36:AE36) -> 0 | AG36: =SUM(AG5:AG35) -> 0 | AH36: =SUM(AH5:AH35) -> 0 | AI36: =SUM(AI5:AI35) -> 0 | AJ36: =SUM(AJ5:AJ35) -> 0 | AK36: =SUM(AK5:AK35) -> 0 | AL36: =AG36+AK36+AH36 -> 0 | AM36: =SUM(AM5:AM35) -> 0 | AO36: =SUM(AO5:AO35) -> 0 | AP36: =SUM(AP5:AP35) -> 0 | AQ36: =SUM(AQ5:AQ35) -> 0 | AR36: =SUM(AR5:AR35) -> 0 | AS36: =SUM(AS5:AS35) -> 0 | AT36: =SUM(AT5:AT35) -> 0 | AV36: =SUM(AV5:AV35) -> 0 | AW36: =SUM(AW5:AW35) -> 0
A37: 전월 | M37: 0 | N37: 0 | O37: 0 | R37: 0 | S37: 0 | T37: 0 | U37: 0 | V37: 0 | W37: 0 | AM37: 0 | AU37: 달성률 | AV37: =AV36/'2026년 폐수반입현황'!AY5 -> #DIV/0! | AW37: =AW36/'2026년 폐수반입현황'!AV5 -> #DIV/0!
A38: 전월대비 | B38: =B36-B37 -> 0 | C38: =C36-C37 -> 0 | D38: =D36-D37 -> 0 | E38: =E36-E37 -> 0 | F38: =F36-F37 -> 0 | G38: =G36-G37 -> 0 | H38: =H36-H37 -> 0 | I38: =I36-I37 -> 0 | ... AK38: =AK36-AK37 -> 0 | AL38: =AG38+AK38+AT38 -> 0 | AM38: =AM36-AM37 -> 0 | AO38: 64.69 | AP38: =AP36-AP37 -> 0 | AQ38: =AQ36-AQ37 -> 0 | AR38: =AR36-AR37 -> 0 | AS38: =AS36-AS37 -> 0 | AT38: =AT36-AT37 -> 0
A39: 년 누계 | M39: 0 | N39: 0 | O39: 0 | AM39: 0
A40: 고농도 침출수 비율 | B40: =B36/P36 -> #DIV/0! | C40: =C36/P36 -> #DIV/0! | D40: =D36/P36 -> #DIV/0! | E40: =E36/P36 -> #DIV/0! | F40: =F36/T36 -> #DIV/0! | G40: =G36/P36 -> #DIV/0! | H40: =H36/P36 -> #DIV/0! | I40: =I36/W36 -> #DIV/0! | J40: =J36/P36 -> #DIV/0! | K40: =K36/P36 -> #DIV/0! | L40: =L36/P36 -> #DIV/0! | P40: =B40+C40+D40+E40+G40+J40+K40+H40+L40 -> #DIV/0! | AY40: 기타일반계 원가절감 데이터
B41: =B40+C40 -> #DIV/0! | D41: =D40+E40+G40+J40+L40+H40 -> #DIV/0! | P41: =B41+C41+D41+E41+G41+J41+K41 -> #DIV/0! | AY41: 월간 | BA41: 기타일반계 | BB41: 포스코양극재
AY42: 반입량 | BA42: =AF36 -> 0 | BB42: =AT36 -> 0
AY43: 약품비 합계 | BA43: 2479 | BB43: 2479
AY44: 탈수처리비용 | BA44: 540 | BB44: 540
AY45: 절감비용 | BA45: =(BA43+BA44)*BA42 -> 0 | BB45: =(BB43+BB44)*BB42 -> 0
AY46: 총 반입량 | BA46: =BA42+BB42+BC42 -> 0
AY47: 총 절감비용 | BA47: =BA46*BA48 -> 0
AY48: 톤당 절감비용 | BA48: 3019
AY49: 절감 약품 종류 : NaOH, H2SO4, Fe2(SO4)3, Cation ★전처리약품
AY52: 2월 | AZ52: 목표 처리량 : 10,640 | BB52: 목표 반입량 : 9,000
AY53: 날짜 | AZ53: 처리량 | BA53: 달성률 | BB53: 반입량 | BC53: 달성률
AY54: 29 | AZ54: =AW36 -> 0 | BA54: =AW37 -> #DIV/0! | BB54: =AV36 -> 0 | BC54: =AV37 -> #DIV/0!

Sheet 3월
A1: 2026년 3월 폐수수탁 일일 반입 및 실적 현황
A2: 구분
B3: 네이처 (경주) | C3: 네이처 (천북) | D3: 아세아테크 돔 | E3: 그린밸리 (이앤컴퍼니) 돔 | G3: 충주그린 (에코비트 그린.충주) 돔 | H3: 포항그린 (그린바이로) | I3: 하동군 생폐처리장 (단가 협의중) | J3: KD환경. 경주 | K3: 리뉴랜드 신경주 돔 | L3: 에코랜드 (제넨바이오) | M3: 예비3 | N3: 예비4 | O3: 예비5 | P3: 침출수 반입량 | Q3: 침출수 반입 비율 (%) | R3: 군위군청 25.2.26~ (최초반입) | S3: 월성 원자력 | T3: 한울 원자력 | U3: 고리 원자력 | V3: 새울 원자력 | W3: 에코프로 머티리얼즈 | X3: 엠엔비 그린어스 | Y3: 영풍석포 25.02.26 일시물량 | Z3: 무안환경 비전 | AA3: 에코프로 예비3 | AB3: 에코프로 예비4 | AC3: 에코프로 예비5 | AD3: SK스페셜티 | AE3: 비정기 기타일반계 | AF3: 기타일반계 합계 | AG3: 성진영농 | AH3: 천보 | AI3: 예비1 | AJ3: 예비2 | AK3: 그 외 일반계 | AL3: 일반계 합계 | AM3: 예비1 | AN3: 예비2 | AO3: 산계 | AP3: 알칼리계 | AQ3: 예비1 | AR3: 예비2 | AS3: 예비3 | AT3: 포스코 퓨처엠 양극재 | AV3: 반입량 (9,000) | AW3: 처리량 (10,640)
A4: 수치 | B4: TOC 2,406 | C4: TOC 2,484 | D4: TOC 3,378 | E4: TOC 895 | G4: TOC 1,002 | H4: TOC 1,053 | J4: TOC 2,618 | K4: TOC 214 | L4: TOC 2,728 | R4: TOC 19 | T4: TOC 5.8 | V4: TOC 34 | W4: TN 1.2 | X4: TN 1.0 | Y4: TN 0.5 | Z4: 7.22재개 | AF4: 화학처리 제외 | AG4: TN 9 | AH4: TN 27 | AT4: 107TK
A5: 1 | P5: =SUM(B5:O5) -> 0 | Q5: =P5/AV5 -> #DIV/0! | AF5: =SUM(R5:AE5) -> 0 | AL5: =AG5+AK5+AH5 -> 0 | AV5: =P5+AF5+AL5+AM5+AP5+AO5+AT5 -> 0
A6: 2 | P6: =SUM(B6:O6) -> 0 | Q6: =P6/AV6 -> #DIV/0! | AF6: =SUM(R6:AE6) -> 0 | AL6: =AG6+AK6+AH6 -> 0 | AV6: =P6+AF6+AL6+AM6+AP6+AO6+AT6 -> 0
A7: 3 | P7: =SUM(B7:O7) -> 0 | Q7: =P7/AV7 -> #DIV/0! | AF7: =SUM(R7:AE7) -> 0 | AL7: =AG7+AK7+AH7 -> 0 | AV7: =P7+AF7+AL7+AM7+AP7+AO7+AT7 -> 0
A8: 4 | P8: =SUM(B8:O8) -> 0 | Q8: =P8/AV8 -> #DIV/0! | AF8: =SUM(R8:AE8) -> 0 | AL8: =AG8+AK8+AH8 -> 0 | AV8: =P8+AF8+AL8+AM8+AP8+AO8+AT8 -> 0
A9: 5 | P9: =SUM(B9:O9) -> 0 | Q9: =P9/AV9 -> #DIV/0! | AF9: =SUM(R9:AE9) -> 0 | AL9: =AG9+AK9+AH9 -> 0 | AV9: =P9+AF9+AL9+AM9+AP9+AO9+AT9 -> 0
A10: 6 | P10: =SUM(B10:O10) -> 0 | Q10: =P10/AV10 -> #DIV/0! | AF10: =SUM(R10:AE10) -> 0 | AL10: =AG10+AK10+AH10 -> 0 | AV10: =P10+AF10+AL10+AM10+AP10+AO10+AT10 -> 0
A11: 7 | P11: =SUM(B11:O11) -> 0 | Q11: =P11/AV11 -> #DIV/0! | AF11: =SUM(R11:AE11) -> 0 | AL11: =AG11+AK11+AH11 -> 0 | AV11: =P11+AF11+AL11+AM11+AP11+AO11+AT11 -> 0
A12: 8 | P12: =SUM(B12:O12) -> 0 | Q12: =P12/AV12 -> #DIV/0! | AF12: =SUM(R12:AE12) -> 0 | AL12: =AG12+AK12+AH12 -> 0 | AV12: =P12+AF12+AL12+AM12+AP12+AO12+AT12 -> 0
A13: 9 | P13: =SUM(B13:O13) -> 0 | Q13: =P13/AV13 -> #DIV/0! | AF13: =SUM(R13:AE13) -> 0 | AL13: =AG13+AK13+AH13 -> 0 | AV13: =P13+AF13+AL13+AM13+AP13+AO13+AT13 -> 0
A14: 10 | P14: =SUM(B14:O14) -> 0 | Q14: =P14/AV14 -> #DIV/0! | AF14: =SUM(R14:AE14) -> 0 | AL14: =AG14+AK14+AH14 -> 0 | AV14: =P14+AF14+AL14+AM14+AP14+AO14+AT14 -> 0
A15: 11 | P15: =SUM(B15:O15) -> 0 | Q15: =P15/AV15 -> #DIV/0! | AF15: =SUM(R15:AE15) -> 0 | AL15: =AG15+AK15+AH15 -> 0 | AV15: =P15+AF15+AL15+AM15+AP15+AO15+AT15 -> 0
A16: 12 | P16: =SUM(B16:O16) -> 0 | Q16: =P16/AV16 -> #DIV/0! | AF16: =SUM(R16:AE16) -> 0 | AL16: =AG16+AK16+AH16 -> 0 | AV16: =P16+AF16+AL16+AM16+AP16+AO16+AT16 -> 0
... A24: 20 | P24: =SUM(B24:O24) -> 0 | Q24: =P24/AV24 -> #DIV/0! | AF24: =SUM(R24:AE24) -> 0 | AL24: =AG24+AK24+AH24 -> 0 | AV24: =P24+AF24+AL24+AM24+AP24+AO24+AT24 -> 0
A25: 21 | G25: 2 | P25: =SUM(B25:O25) -> 2 | Q25: =P25/AV25 -> 1 | AF25: =SUM(R25:AE25) -> 0 | AL25: =AG25+AK25+AH25 -> 0 | AV25: =P25+AF25+AL25+AM25+AP25+AO25+AT25 -> 2
A26: 22 | P26: =SUM(B26:O26) -> 0 | Q26: =P26/AV26 -> #DIV/0! | AF26: =SUM(R26:AE26) -> 0 | AL26: =AG26+AK26+AH26 -> 0 | AV26: =P26+AF26+AL26+AM26+AP26+AO26+AT26 -> 0
A27: 23 | H27: 2 | P27: =SUM(B27:O27) -> 2 | Q27: =P27/AV27 -> 1 | AF27: =SUM(R27:AE27) -> 0 | AL27: =AG27+AK27+AH27 -> 0 | AV27: =P27+AF27+AL27+AM27+AP27+AO27+AT27 -> 2
A28: 24 | P28: =SUM(B28:O28) -> 0 | Q28: =P28/AV28 -> #DIV/0! | AF28: =SUM(R28:AE28) -> 0 | AL28: =AG28+AK28+AH28 -> 0 | AV28: =P28+AF28+AL28+AM28+AP28+AO28+AT28 -> 0
A29: 25 | H29: 2 | P29: =SUM(B29:O29) -> 2 | Q29: =P29/AV29 -> 1 | AF29: =SUM(R29:AE29) -> 0 | AL29: =AG29+AK29+AH29 -> 0 | AV29: =P29+AF29+AL29+AM29+AP29+AO29+AT29 -> 2
A30: 26 | L30: 2 | P30: =SUM(B30:O30) -> 2 | Q30: =P30/AV30 -> 1 | AF30: =SUM(R30:AE30) -> 0 | AL30: =AG30+AK30+AH30 -> 0 | AV30: =P30+AF30+AL30+AM30+AP30+AO30+AT30 -> 2
A31: 27 | P31: =SUM(B31:O31) -> 0 | Q31: =P31/AV31 -> #DIV/0! | AF31: =SUM(R31:AE31) -> 0 | AL31: =AG31+AK31+AH31 -> 0 | AV31: =P31+AF31+AL31+AM31+AP31+AO31+AT31 -> 0
A32: 2 | P32: =SUM(B32:O32) -> 0 | Q32: =P32/AV32 -> #DIV/0! | AF32: =SUM(R32:AE32) -> 0 | AL32: =AG32+AK32+AH32 -> 0 | AV32: =P32+AF32+AL32+AM32+AP32+AO32+AT32 -> 0
A33: 29 | P33: =SUM(B33:O33) -> 0 | Q33: =P33/AV33 -> #DIV/0! | AF33: =SUM(R33:AE33) -> 0 | AL33: =AG33+AK33+AH33 -> 0 | AV33: =P33+AF33+AL33+AM33+AP33+AO33+AT33 -> 0
A34: 30 | P34: =SUM(B34:O34) -> 0 | Q34: =P34/AV34 -> #DIV/0! | AF34: =SUM(R34:AE34) -> 0 | AL34: =AG34+AK34+AH34 -> 0 | AV34: =P34+AF34+AL34+AM34+AP34+AO34+AT34 -> 0 | AX34: `
A35: 31 | P35: =SUM(B35:O35) -> 0 | Q35: =P35/AV35 -> #DIV/0! | AF35: =SUM(R35:AE35) -> 0 | AL35: =AG35+AK35+AH35 -> 0 | AV35: =P35+AF35+AL35+AM35+AP35+AO35+AT35 -> 0
A36: 월계 | B36: =SUM(B5:B35) -> 0 | C36: =SUM(C5:C35) -> 0 | D36: =SUM(D5:D35) -> 0 | E36: =SUM(E5:E35) -> 0 | F36: =SUM(F5:F35) -> 0 | G36: =SUM(G5:G35) -> 2 | H36: =SUM(H5:H35) -> 4 | I36: =SUM(I5:I35) -> 0 | ... O36: =SUM(O5:O35) -> 0 | P36: =SUM(B36:O36) -> 8 | Q36: =AVERAGE(Q5:Q35) -> #DIV/0! | R36: =SUM(R5:R35) -> 0 | S36: =SUM(S5:S35) -> 0 | T36: =SUM(T5:T35) -> 0 | U36: =SUM(U5:U35) -> 0 | V36: =SUM(V5:V35) -> 0 | W36: =SUM(W5:W35) -> 0 | X36: =SUM(X5:X35) -> 0 | Y36: =SUM(Y5:Y35) -> 0 | ... AE36: =SUM(AE5:AE35) -> 0 | AF36: =SUM(R36:AE36) -> 0 | AG36: =SUM(AG5:AG35) -> 0 | AH36: =SUM(AH5:AH35) -> 0 | AI36: =SUM(AI5:AI35) -> 0 | AJ36: =SUM(AJ5:AJ35) -> 0 | AK36: =SUM(AK5:AK35) -> 0 | AL36: =AG36+AK36+AH36 -> 0 | AM36: =SUM(AM5:AM35) -> 0 | AO36: =SUM(AO5:AO35) -> 0 | AP36: =SUM(AP5:AP35) -> 0 | AQ36: =SUM(AQ5:AQ35) -> 0 | AR36: =SUM(AR5:AR35) -> 0 | AS36: =SUM(AS5:AS35) -> 0 | AT36: =SUM(AT5:AT35) -> 0 | AV36: =SUM(AV5:AV35) -> 8 | AW36: =SUM(AW5:AW35) -> 0
A37: 전월 | M37: 0 | N37: 0 | O37: 0 | R37: 0 | S37: 0 | T37: 0 | U37: 0 | V37: 0 | W37: 0 | AM37: 0 | AU37: 달성률 | AV37: =AV36/'2026년 폐수반입현황'!AY5 -> #DIV/0! | AW37: =AW36/'2026년 폐수반입현황'!AV5 -> #DIV/0!
A38: 전월대비 | B38: =B36-B37 -> 0 | C38: =C36-C37 -> 0 | D38: =D36-D37 -> 0 | E38: =E36-E37 -> 0 | F38: =F36-F37 -> 0 | G38: =G36-G37 -> 2 | H38: =H36-H37 -> 4 | I38: =I36-I37 -> 0 | ... AK38: =AK36-AK37 -> 0 | AL38: =AG38+AK38+AT38 -> 0 | AM38: =AM36-AM37 -> 0 | AO38: 64.69 | AP38: =AP36-AP37 -> 0 | AQ38: =AQ36-AQ37 -> 0 | AR38: =AR36-AR37 -> 0 | AS38: =AS36-AS37 -> 0 | AT38: =AT36-AT37 -> 0
A39: 년 누계 | M39: 0 | N39: 0 | O39: 0 | AM39: 0
A40: 고농도 침출수 비율 | B40: =B36/P36 -> 0 | C40: =C36/P36 -> 0 | D40: =D36/P36 -> 0 | E40: =E36/P36 -> 0 | F40: =F36/T36 -> #DIV/0! | G40: =G36/P36 -> 0.25 | H40: =H36/P36 -> 0.5 | I40: =I36/W36 -> #DIV/0! | J40: =J36/P36 -> 0 | K40: =K36/P36 -> 0 | L40: =L36/P36 -> 0.25 | P40: =B40+C40+D40+E40+G40+J40+K40+H40+L40 -> 1 | AY40: 기타일반계 원가절감 데이터
B41: =B40+C40 -> 0 | D41: =D40+E40+G40+J40+L40+H40 -> 1 | P41: =B41+C41+D41+E41+G41+J41+K41 -> 1 | AY41: 월간 | BA41: 기타일반계 | BB41: 포스코양극재
AY42: 반입량 | BA42: =AF36 -> 0 | BB42: =AT36 -> 0
AY43: 약품비 합계 | BA43: 2479 | BB43: 2479
AY44: 탈수처리비용 | BA44: 540 | BB44: 540
AY45: 절감비용 | BA45: =(BA43+BA44)*BA42 -> 0 | BB45: =(BB43+BB44)*BB42 -> 0
AY46: 총 반입량 | BA46: =BA42+BB42+BC42 -> 0
AY47: 총 절감비용 | BA47: =BA46*BA48 -> 0
...

Sheet 2026년 폐수반입현황
A1: 2026년 폐수수탁 반입 현황
A2: 구 분 | B2: 네이처 .경주 | C2: 네이처 .천북 | D2: 아세아 테크 | E2: 그린밸리 | F2: 에코랜드 | G2: 에코비트 그린.충주 | H2: 그린 바이로 | I2: 하동군 생폐처리장 | J2: KD환경 | K2: 리뉴랜드 신경주 | L2: 에코랜드 (제넨바이오) | M2: 예비3 | N2: 예비4 | O2: 예비5 | P2: 고농도 침출수 반입량 | Q2: 침출수 반입 비율(%) | R2: 군위군청 | T2: 한울 원자력 | U2: 고리 원자력 | V2: 새울 원자력 | W2: 에코프로 머티리얼즈 | X2: 엠엔비 그린어스 | Y2: 영풍석포 2공장 | Z2: 무안 환경 비전 | AA2: 에코프로 예비3 | AB2: 에코프로 예비4 | AC2: 에코프로 예비5 | AD2: SK스페셜티 | AE2: 비정기 | AF2: 기타 일반계 | AG2: 성진영농 | AH2: 천보 | AI2: 예비1 | AJ2: 예비2 | AK2: 그 외 일반계 | AL2: 일반계 합계 | AM2: 예비1 | AN2: 예비2 | AO2: 산계 | AP2: 알칼리계 | AQ2: 예비1 | AR2: 예비2 | AS2: 예비3 | AT2: 포스코 퓨처엠 양극재 | AV2: 처리계획 | AW2: 처리량 | AX2: 달성률 | AY2: 반입계획 | AZ2: 반입량 | BA2: 달성률
B3: TOC 1,686 | C3: TOC 2,484 | D3: TOC 3,378 | E3: TOC 895 | F3: TOC 1,909 | G3: TOC 1,059 | H3: TOC 1,053 | J3: TOC 395.5 | K3: TOC 214 | L3: TOC 2,728 | R3: TOC 19 | T3: TOC 5.8 | V3: TOC 34 | W3: TN 1.2 | X3: TN 1.0 | Y3: TN 0.5 | AH3: TOC 32.9, TN 27
A4: 2024년 반입량 | B4: 14353.76 | C4: 4589.23 | D4: 1172.95 | E4: 12324.82 | F4: 0 | G4: 1520 | H4: 8958 | I4: 0 | J4: 5710 | K4: 51 | M4: 0 | N4: 0 | O4: 0 | P4: 48679.22 | Q4: 0.40307706 | S4: 0 | T4: 8325.8 | U4: 0 | V4: 89 | W4: 1419.03 | X4: 1280.94 | Y4: 0 | Z4: 0 | AA4: 0 | AB4: 0 | AC4: 0 | AD4: 0 | AE4: 1457.76 | AF4: 13426.62 | AG4: 5916.32 | AH4: 6302.54 | AI4: 0 | AJ4: 0 | AK4: 35203.75 | AL4: 35204 | AM4: 0 | AN4: 0 | AO4: 2332 | AP4: 1745 | AQ4: 0 | AR4: 0 | AS4: 0 | AT4: 6884 | AV4: 113335 | AW4: 121879 | AX4: 1.0759135 | AY4: 103600 | AZ4: 121979 | BA4: 1.1782349
A5: 1월 | AX5: =AW5/AV5 -> #DIV/0! | BA5: =AZ5/AY5 -> #DIV/0!
A6: 2월 | AX6: =AW6/AV6 -> #DIV/0! | BA6: =AZ6/AY6 -> #DIV/0!
A7: 3월 | AX7: =AW7/AV7 -> #DIV/0! | BA7: =AZ7/AY7 -> #DIV/0!
A8: 4월 | AX8: =AW8/AV8 -> #DIV/0! | BA8: =AZ8/AY8 -> #DIV/0!
A9: 5월 | AX9: =AW9/AV9 -> #DIV/0! | BA9: =AZ9/AY9 -> #DIV/0!
A10: 6월 | AX10: =AW10/AV10 -> #DIV/0! | BA10: =AZ10/AY10 -> #DIV/0!
A11: 7월 | AX11: =AW11/AV11 -> #DIV/0! | BA11: =AZ11/AY11 -> #DIV/0!
A12: 8월 | AX12: =AW12/AV12 -> #DIV/0! | BA12: =AZ12/AY12 -> #DIV/0!
A13: 9월 | AX13: =AW13/AV13 -> #DIV/0! | BA13: =AZ13/AY13 -> #DIV/0!
A14: 10월 | AX14: =AW14/AV14 -> #DIV/0! | BA14: =AZ14/AY14 -> #DIV/0!
A15: 11월 | AX15: =AW15/AV15 -> #DIV/0! | BA15: =AZ15/AY15 -> #DIV/0!
A16: 12월 | AX16: =AW16/AV16 -> #DIV/0! | BA16: =AZ16/AY16 -> #DIV/0!
A17: 합계 | B17: =SUM(B5:B16) -> 0 | C17: =SUM(C5:C16) -> 0 | D17: =SUM(D5:D16) -> 0 | E17: =SUM(E5:E16) -> 0 | F17: =SUM(F5:F16) -> 0 | G17: =SUM(G5:G16) -> 0 | H17: =SUM(H5:H16) -> 0 | I17: =SUM(I5:I16) -> 0 | ... O17: =SUM(O5:O16) -> 0 | P17: =SUM(B17:L17) -> 0 | Q17: =AVERAGE(Q5:Q16) -> #DIV/0! | R17: =SUM(R5:R16) -> 0 | S17: =SUM(S5:S16) -> 0 | T17: =SUM(T5:T16) -> 0 | U17: =SUM(U5:U16) -> 0 | V17: =SUM(V5:V16) -> 0 | W17: =SUM(W5:W16) -> 0 | X17: =SUM(X5:X16) -> 0 | Y17: =SUM(Y5:Y16) -> 0 | ... AT17: =SUM(AT5:AT16) -> 0 | AV17: =SUM(AV5:AV16) -> 0 | AW17: =SUM(AW5:AW16) -> 0 | AY17: =SUM(AY5:AY16) -> 0 | AZ17: =SUM(AZ5:AZ16) -> 0
A18: 연평균 | B18: =AVERAGEA(B5:B16) -> #DIV/0! | C18: =AVERAGEA(C5:C16) -> #DIV/0! | D18: =AVERAGEA(D5:D16) -> #DIV/0! | E18: =AVERAGEA(E5:E16) -> #DIV/0! | F18: =AVERAGEA(F5:F16) -> #DIV/0! | G18: =AVERAGEA(G5:G16) -> #DIV/0! | H18: =AVERAGEA(H5:H16) -> #DIV/0! | I18: =AVERAGEA(I5:I16) -> #DIV/0! | ... AW18: =AVERAGEA(AW5:AW16) -> #DIV/0! | AX18: =AVERAGEA(AX5:AX12) -> #DIV/0! | AY18: =AVERAGEA(AY5:AY16) -> #DIV/0! | AZ18: =AVERAGEA(AZ5:AZ16) -> #DIV/0! | BA18: =AVERAGEA(BA5:BA12) -> #DIV/0!
A19: 연비율 | B19: =B18/P18 -> #DIV/0! | C19: =C18/P18 -> #DIV/0! | D19: =D18/P18 -> #DIV/0! | E19: =E18/P18 -> #DIV/0! | G19: =G18/P18 -> #DIV/0! | H19: =H18/P18 -> #DIV/0! | J19: =J18/P18 -> #DIV/0! | K19: =K18/P18 -> #DIV/0! | L19: =L18/P18 -> #DIV/0! | P19: =SUM(B19:O19) -> #DIV/0!
A20: 특이 사항 | B20: 1. 9월 무안환경비전(침출수)을 기타일반계로 투입하여 기타일반계 원가절감에 포함되었습니다. 2. 세아특수강 폐수에 고형분이 다량 함유되어 실험중입니다.
A24: 2024년 기타일반계 원가절감
A26: 업체명 | C26: 기타 일반계 | D26: 무안 환경비전 | E26: 포스코 퓨처엠 | F26: SK | G26: 합계
A27: 반입량 | C27: =AF4 -> 13426.62 | D27: 854 | E27: =AT4 -> 6884 | F27: 5642 | G27: =F27+E27+D27+C27 -> 26806.62
A28: 약품비(2,479) | C28: 3019
A29: 탈수처리비(540)
A30: 절감비용 | C30: =C27*C28 -> 40534966 | D30: =D27*C28 -> 2578226 | E30: =E27*C28 -> 20782796 | F30: =F27*C28 -> 17033198 | G30: =F30+E30+D30+C30 -> 80929186
A33: 2025년 1분기 기타일반계 원가절감
A35: 업체명 | C35: 기타 일반계 | D35: 군위군청 | E35: 포스코 퓨처엠 | F35: SK | G35: 합계
A36: 반입량 | C36: =AF17 -> 0 | D36: =L17 -> 0 | E36: =AT17 -> 0 | G36: =F36+E36+D36+C36 -> 0
A37: 약품비(2,479) | C37: 3019
A38: 탈수처리비(540)
A39: 절감비용 | C39: =C36*C37 -> 0 | D39: =D36*C37 -> 0 | E39: =E36*C37 -> 0 | F39: =F36*C37 -> 0 | G39: =F39+E39+D39+C39 -> 0
A47: ▶기타일반계 화학처리비 산출
A48: 구분 | B48: 원수 | C48: NaOH | D48: Fe2(SO4)3 | E48: 슬러지 | F48: 비고
A49: 단가 | B49: - | C49: 370원/kg | D49: 82원/kg | E49: 145원/㎏
A50: 사용량(㎖) | B50: 500㎖ | C50: 2 | D50: 1 | E50: 620㎎/ℓ
A51: 환산(ℓ) | B51: 1㎥ | C51: 4 | D51: 2 | E51: 620g
A52: 환산(㎏) | C52: 6 | D52: 3.156 | E52: 2.48㎏
A53: 금액(원/톤) | B53: - | C53: 2220 | D53: 258.792 | E53: 540 | F53: 3018.792
A54: 비고 | B54: 기타일반계 폐수 Jar-Test | C54: 비중 1.5 | D54: 비중 1.578 | E54: 함수율 포함 | F54: 3,100원 적용

Sheet 20~ 반입현황
B2: ▶년도별 폐수수탁 성상별 반입 현황 | L2: ▶성상별 반입 비율
B3: 구 분 | D3: 2020년 | E3: 2021년 | F3: 2022년 | G3: 2023년 | H3: 2024년 | I3: 2025년 | J3: 전년대비 | L3: 성상 구분 | M3: 2020년 | N3: 2021년 | O3: 2022년 | P3: 2023년 | Q3: 2024년 | R3: 2025년
B4: 1 | C4: 네이처 .경주 | J4: =I4-H4 -> 0 | L4: 고농도침출수
B5: 2 | C5: 네이처 .천북 | J5: =I5-H5 -> 0 | L5: 기타일반계
B6: 3 | C6: 아세아테크 | J6: =I6-H6 -> 0 | L6: 그외 폐수
B7: 4 | C7: 그린밸리(이앤컴퍼니) | J7: =I7-H7 -> 0 | L7: 합 계 | M7: =SUM(M4:M6) -> 0 | N7: =SUM(N4:N6) -> 0 | O7: =SUM(O4:O6) -> 0 | P7: =SUM(P4:P6) -> 0 | Q7: =SUM(Q4:Q6) -> 0 | R7: =SUM(R4:R6) -> 0
B8: 5 | C8: 에코랜드(제넨바이오) | J8: =I8-H8 -> 0
B9: 6 | C9: 충주그린(구.에코비트그린.충주) | J9: =I9-H9 -> 0
B10: 7 | C10: 포항그린(구.그린바이로) | J10: =I10-H10 -> 0
B11: 8 | C11: KD환경 | J11: =I11-H11 -> 0
B12: 9 | C12: 나곡매립장(울진) | J12: =I12-H12 -> 0
B13: 10 | C13: 그린파워, 세종시,하동 | J13: =I13-H13 -> 0
B14: 고농도침출수 반입량 | D14: =SUM(D4:D13) -> 0 | E14: =SUM(E4:E13) -> 0 | F14: =SUM(F4:F13) -> 0 | G14: =SUM(G4:G13) -> 0 | H14: =SUM(H4:H13) -> 0 | I14: =SUM(I4:I13) -> 0 | J14: =I14-H14 -> 0
B15: 침출수반입 비율(%) | D15: =D14/D35 -> #DIV/0! | E15: =E14/E35 -> #DIV/0! | F15: =F14/F35 -> #DIV/0! | G15: =G14/G35 -> #DIV/0! | H15: =H14/H35 -> #DIV/0! | I15: =I14/I35 -> #DIV/0! | J15: =I15-H15 -> #DIV/0!
B16: 11 | C16: 무안환경비전 | J16: =I16-H16 -> 0
B17: 12 | C17: 월성원자력 | J17: =I17-H17 -> 0
B18: 13 | C18: 한울원자력 | J18: =I18-H18 -> 0
B19: 14 | C19: 고리원자력 | J19: =I19-H19 -> 0
B20: 15 | C20: 새울원자력 | J20: =I20-H20 -> 0
B21: 16 | C21: 에코프로머티리얼즈 | J21: =I21-H21 -> 0
B22: 17 | C22: 엠엔비그린어스 | J22: =I22-H22 -> 0
B23: 18 | C23: SK스페셜티 | J23: =I23-H23 -> 0
B24: 기타일반계 반입량 | D24: =SUM(D16:D23) -> 0 | E24: =SUM(E16:E23) -> 0 | F24: =SUM(F16:F23) -> 0 | G24: =SUM(G16:G23) -> 0 | H24: =SUM(H16:H23) -> 0 | I24: =SUM(I16:I23) -> 0 | J24: =I24-H24 -> 0
B25: 기타일반계 반입비율(%) | D25: =D24/D35 -> #DIV/0! | E25: =E24/E35 -> #DIV/0! | F25: =F24/F35 -> #DIV/0! | G25: =G24/G35 -> #DIV/0! | H25: =H24/H35 -> #DIV/0! | I25: =I24/I35 -> #DIV/0! | J25: =I25-H25 -> #DIV/0!
B26: 19 | C26: 성진영농 | J26: =I26-H26 -> 0
B27: 20 | C27: 천보 | J27: =I27-H27 -> 0
B28: 21 | C28: 일반계 1,2,3 | J28: =I28-H28 -> 0
B29: 22 | C29: 산계 | J29: =I29-H29 -> 0
B30: 23 | C30: 알칼리계 | J30: =I30-H30 -> 0
B31: 24 | C31: 두산건설 | J31: =I31-H31 -> 0
B32: 25 | C32: 포스코퓨처엠양,양극재 | J32: =I32-H32 -> 0
B33: 그 외 반입량 | D33: =SUM(D26:D32) -> 0 | E33: =SUM(E26:E32) -> 0 | F33: =SUM(F26:F32) -> 0 | G33: =SUM(G26:G32) -> 0 | H33: =SUM(H26:H32) -> 0 | I33: =SUM(I26:I32) -> 0 | J33: =I33-H33 -> 0
B34: 반입량 비율 | D34: =D33/D35 -> #DIV/0! | E34: =E33/E35 -> #DIV/0! | F34: =F33/F35 -> #DIV/0! | G34: =G33/G35 -> #DIV/0! | H34: =H33/H35 -> #DIV/0! | I34: =I33/I35 -> #DIV/0! | J34: =I34-H34 -> #DIV/0!
B35: 총 합계 | J35: =I35-H35 -> 0
